Traceback (most recent call last):
  File "/Users/runner/micromamba-root/envs/cordex-tutorials/lib/python3.10/site-packages/jupyter_cache/executors/utils.py", line 58, in single_nb_execution
    executenb(
  File "/Users/runner/micromamba-root/envs/cordex-tutorials/lib/python3.10/site-packages/nbclient/client.py", line 1305, in execute
    return NotebookClient(nb=nb, resources=resources, km=km, **kwargs).execute()
  File "/Users/runner/micromamba-root/envs/cordex-tutorials/lib/python3.10/site-packages/jupyter_core/utils/__init__.py", line 166, in wrapped
    return loop.run_until_complete(inner)
  File "/Users/runner/micromamba-root/envs/cordex-tutorials/lib/python3.10/asyncio/base_events.py", line 649, in run_until_complete
    return future.result()
  File "/Users/runner/micromamba-root/envs/cordex-tutorials/lib/python3.10/site-packages/nbclient/client.py", line 705, in async_execute
    await self.async_execute_cell(
  File "/Users/runner/micromamba-root/envs/cordex-tutorials/lib/python3.10/site-packages/nbclient/client.py", line 1058, in async_execute_cell
    await self._check_raise_for_error(cell, cell_index, exec_reply)
  File "/Users/runner/micromamba-root/envs/cordex-tutorials/lib/python3.10/site-packages/nbclient/client.py", line 914, in _check_raise_for_error
    raise CellExecutionError.from_cell_and_msg(cell, exec_reply_content)
nbclient.exceptions.CellExecutionError: An error occurred while executing the following cell:
------------------
ds_change = ds.drop("time_bnds").copy()
%time ds_change["tas"] = ds_change.tas - ds_change.tas.sel(time=slice("1981", "2010")).mean(
    "time"
)
------------------


[0;36m  Cell [0;32mIn[4], line 3[0;36m[0m
[0;31m    "time"[0m
[0m    ^[0m
[0;31mIndentationError[0m[0;31m:[0m unexpected indent


